Workbook

Sheet Dashboard
B2: DASHBOARD - FINANCEIRO DA FEIRA DE MERCADO
B4: Faturamento Fechado | D4: Gasto Total Previsto | F4: Resultado Hoje | H4: Cotas Vendidas / Total
B5: =SUMIFS(Vendas!H5:H36,Vendas!F5:F36,"Fechado") -> 212000 | D5: ='Gastos Previstos'!C50 -> 184596.89 | F5: ='Previsão de Receita'!C9 -> 27403.11 | H5: =SUMPRODUCT((Vendas!F5:F36="Fechado")*1)&" / "&'Parâmetros'!E28 -> 25 / 73
B8: % do Equilíbrio Atingido | D8: Já Pago (Realizado) | F8: Caixa no Pior Mês | H8: Faturamento Máx (tabela)
B9: =IF('Previsão de Receita'!C7=0,0,'Previsão de Receita'!C8/'Previsão de Receita'!C7) -> 1.2617376 | D9: ='Gastos Realizados'!L33 -> 27306.86 | F9: =MIN('Fluxo de Caixa'!C17:H17) -> -20156.89 | H9: ='Parâmetros'!H28 -> 349000
B13: Vendas por Pacote | F13: Faturamento por EJ
B14: Pacote | C14: Fechados | D14: Faturamento | F14: EJ | G14: Faturamento
B15: Executivo | C15: =SUMPRODUCT((Vendas!$D$5:$D$36="Executivo")*(Vendas!$F$5:$F$36="Fechado")) -> 4 | D15: =SUMPRODUCT((Vendas!$D$5:$D$36="Executivo")*(Vendas!$F$5:$F$36="Fechado")*Vendas!$H$5:$H$36) -> 16000 | F15: Produção Jr | G15: =SUMPRODUCT((Vendas!$B$5:$B$36="Produção Jr")*(Vendas!$F$5:$F$36="Fechado")*Vendas!$H$5:$H$36) -> 163000
B16: Bronze | C16: =SUMPRODUCT((Vendas!$D$5:$D$36="Bronze")*(Vendas!$F$5:$F$36="Fechado")) -> 13 | D16: =SUMPRODUCT((Vendas!$D$5:$D$36="Bronze")*(Vendas!$F$5:$F$36="Fechado")*Vendas!$H$5:$H$36) -> 97500 | F16: EESC Jr | G16: =SUMPRODUCT((Vendas!$B$5:$B$36="EESC Jr")*(Vendas!$F$5:$F$36="Fechado")*Vendas!$H$5:$H$36) -> 49000
B17: Prata | C17: =SUMPRODUCT((Vendas!$D$5:$D$36="Prata")*(Vendas!$F$5:$F$36="Fechado")) -> 6 | D17: =SUMPRODUCT((Vendas!$D$5:$D$36="Prata")*(Vendas!$F$5:$F$36="Fechado")*Vendas!$H$5:$H$36) -> 68500
B18: Ouro | C18: =SUMPRODUCT((Vendas!$D$5:$D$36="Ouro")*(Vendas!$F$5:$F$36="Fechado")) -> 2 | D18: =SUMPRODUCT((Vendas!$D$5:$D$36="Ouro")*(Vendas!$F$5:$F$36="Fechado")*Vendas!$H$5:$H$36) -> 30000
B19: Patrocínio | C19: =SUMPRODUCT((Vendas!$D$5:$D$36="Patrocínio")*(Vendas!$F$5:$F$36="Fechado")) -> 0 | D19: =SUMPRODUCT((Vendas!$D$5:$D$36="Patrocínio")*(Vendas!$F$5:$F$36="Fechado")*Vendas!$H$5:$H$36) -> 0
B22: Previsto × Realizado
B23: Categoria | C23: Previsto | D23: Realizado | E23: % Executado
B24: Fixos Dtrip | C24: ='Gastos Previstos'!C22 -> 69220.24 | D24: =SUMIFS('Gastos Realizados'!$L$5:$L$31,'Gastos Realizados'!$B$5:$B$31,"Fixo Dtrip") -> 16838 | E24: =IF(C24=0,0,D24/C24) -> 0.24325255
B25: Estandes | C25: ='Gastos Previstos'!C29 -> 79900 | D25: 0 | E25: =IF(C25=0,0,D25/C25) -> 0
B26: Outros | C26: ='Gastos Previstos'!C48 -> 35476.65 | D26: =SUMIFS('Gastos Realizados'!$L$5:$L$31,'Gastos Realizados'!$B$5:$B$31,"Outros") -> 10468.86 | E26: =IF(C26=0,0,D26/C26) -> 0.29509156

Sheet Gastos Previstos
B2: GASTOS PREVISTOS
B4: Descrição | C4: Total (R$) | D4: Jul | E4: Ago | F4: Set | G4: Out | H4: Nov | I4: Dez
B5: GASTOS FIXOS DTRIP (LGDM)
B6: Gestão da Feira (contrato LGDM) | C6: =SUM(D6:I6) -> 25257 | D6: 8419 | E6: 8419 | F6: 8419
B7: Lounge Expo 1, 2, 3 e 4 | C7: =SUM(D7:I7) -> 3060 | F7: 3060
B8: Backdrop de fotos | C8: =SUM(D8:I8) -> 2933.5 | F8: 2933.5
B9: Roda de conversa | C9: =SUM(D9:I9) -> 4532 | F9: 4532
B10: Impostos | C10: =SUM(D10:I10) -> 10227.24 | F10: 10227.24
B11: FECHAMENTO AMBIENTES - CORREDOR | C11: =SUM(D11:I11) -> 560 | F11: 560
B12: TOTENS DE SINALIZAÇÃO COM TV | C12: =SUM(D12:I12) -> 900 | F12: 900
B13: ÁREA COOFFE | C13: =SUM(D13:I13) -> 1980 | F13: 1980
B14: FECHAMENTO AMBIENTES - ESCADA/COOFEE | C14: =SUM(D14:I14) -> 440 | F14: 440
B15: TOTEM DE SINALIZAÇÃO MDF | C15: =SUM(D15:I15) -> 880 | F15: 880
B16: ATIVAÇÃO - CARRINHO DE PIPOCA COM OPERADOR | C16: =SUM(D16:I16) -> 1000 | F16: 1000
B17: AUDITÓRIO LUIS GASTÃO - COMUNICAÇÃO VISUAL PALESTRAS | C17: =SUM(D17:I17) -> 1595 | F17: 1595
B18: ATIVAÇÃO - BACKDROP DE ASSINATURA (L)2,30m X (A)2,30m | C18: =SUM(D18:I18) -> 920 | F18: 920
... B21: Credenciamento | C21: =SUM(D21:I21) -> 8685.5 | F21: 8685.5
B22: TOTAL FIXOS DTRIP | C22: =SUM(C6:C21) -> 69220.24 | D22: =SUM(D6:D21) -> 8419 | E22: =SUM(E6:E21) -> 8419 | F22: =SUM(F6:F21) -> 52382.24 | G22: =SUM(G6:G21) -> 0 | H22: =SUM(H6:H21) -> 0 | I22: =SUM(I6:I21) -> 0
B23: GASTOS VARIÁVEIS DTRIP (estandes)
B24: Executivo (4 cotas × R$ 1.500) | C24: =SUM(D24:I24) -> 6000 | F24: 6000
B25: Bronze (13 cotas × R$ 2.950) | C25: =SUM(D25:I25) -> 38350 | F25: 38350
B26: Prata (6 cotas × R$ 3.950) | C26: =SUM(D26:I26) -> 23700 | F26: 23700
B27: Ouro (2 cotas × R$ 5.925) | C27: =SUM(D27:I27) -> 11850 | F27: 11850
B28: Patrocínio (0 cotas × R$ 0) | C28: =SUM(D28:I28) -> 0 | E28: 0 | F28: 0
B29: TOTAL VARIÁVEIS DTRIP | C29: =SUM(C24:C28) -> 79900 | D29: =SUM(D24:D28) -> 0 | E29: =SUM(E24:E28) -> 0 | F29: =SUM(F24:F28) -> 79900 | G29: =SUM(G24:G28) -> 0 | H29: =SUM(H24:H28) -> 0 | I29: =SUM(I24:I28) -> 0
B30: OUTROS GASTOS
B31: Marketing | C31: =SUM(D31:I31) -> 1440 | E31: 1440
B32: EJUDI (6x) | C32: 2880 | D32: 480 | E32: 480 | F32: 480 | G32: 480
B33: Camisetas | C33: =2280 -> 2280 | D33: 1140 | E33: 1140
B34: Ambulância | C34: =SUM(D34:I34) -> 2150 | F34: 2150
B35: Transporte USP Pirassununga <> UFSCar | C35: =SUM(D35:I35) -> 615 | F35: 615
B36: Ventiladores | C36: =SUM(D36:I36) -> 2840 | E36: 0 | F36: 2840
B37: Sorteios | C37: =SUM(D37:I37) -> 2721.01 | F37: 2721.01
B38: Crachás | C38: =SUM(D38:I38) -> 1779.23 | E38: 1779.23
B39: Segurança | C39: =SUM(D39:I39) -> 800 | F39: 800
B40: Limpeza | C40: =SUM(D40:I40) -> 1650 | F40: 1650
B41: Cartazes | C41: =SUM(D41:I41) -> 50 | E41: 50
B42: Banners | C42: =SUM(D42:I42) -> 96 | E42: 96
B43: Bolsas Brindes | C43: =SUM(D43:I43) -> 4375.41 | E43: 2000 | F43: 2375.41
B44: Internet | C44: =SUM(D44:I44) -> 3800 | F44: 3800
...

Sheet Vendas
B2: VENDAS E RECEBIMENTOS
B4: EJ Responsável | C4: Empresa | D4: Pacote | E4: Preço Tabela | F4: Status | G4: Data Fech. | H4: Valor Contratado | I4: Custo Estande | J4: Margem | K4: P1 Data | L4: P1 Valor | M4: P2 Data | N4: P2 Valor | O4: P3 Data | P4: P3 Valor | Q4: Soma Parc. | R4: OK?
B5: Produção Jr | C5: Tractian | D5: Ouro | E5: {=IFERROR(INDEX('Parâmetros'!$C$23:$C$27,MATCH(D5,'Parâmetros'!$B$23:$B$27,0)),"")} -> 15000 | F5: Fechado | H5: 15000 | I5: {=IFERROR(INDEX('Parâmetros'!$F$23:$F$27,MATCH(D5,'Parâmetros'!$B$23:$B$27,0)),"")} -> 5925 | J5: =IF(H5="","",H5-I5) -> 9075 | K5: 46204 | L5: 7500 | M5: 46204 | N5: 7500 | Q5: =L5+N5+P5 -> 15000 | R5: =IF(H5="","",IF(ROUND(Q5-H5,2)=0,"OK","≠")) -> OK
B6: Produção Jr | C6: Itaú | D6: Ouro | E6: {=IFERROR(INDEX('Parâmetros'!$C$23:$C$27,MATCH(D6,'Parâmetros'!$B$23:$B$27,0)),"")} -> 15000 | F6: Fechado | H6: 15000 | I6: {=IFERROR(INDEX('Parâmetros'!$F$23:$F$27,MATCH(D6,'Parâmetros'!$B$23:$B$27,0)),"")} -> 5925 | J6: =IF(H6="","",H6-I6) -> 9075 | K6: 46204 | L6: 15000 | Q6: =L6+N6+P6 -> 15000 | R6: =IF(H6="","",IF(ROUND(Q6-H6,2)=0,"OK","≠")) -> OK
B7: Produção Jr | C7: Artefact | D7: Prata | E7: {=IFERROR(INDEX('Parâmetros'!$C$23:$C$27,MATCH(D7,'Parâmetros'!$B$23:$B$27,0)),"")} -> 11500 | F7: Fechado | H7: 11500 | I7: {=IFERROR(INDEX('Parâmetros'!$F$23:$F$27,MATCH(D7,'Parâmetros'!$B$23:$B$27,0)),"")} -> 3950 | J7: =IF(H7="","",H7-I7) -> 7550 | K7: 46256 | L7: 11500 | Q7: =L7+N7+P7 -> 11500 | R7: =IF(H7="","",IF(ROUND(Q7-H7,2)=0,"OK","≠")) -> OK
B8: Produção Jr | C8: Luz | D8: Bronze | E8: {=IFERROR(INDEX('Parâmetros'!$C$23:$C$27,MATCH(D8,'Parâmetros'!$B$23:$B$27,0)),"")} -> 7500 | F8: Fechado | H8: 7500 | I8: {=IFERROR(INDEX('Parâmetros'!$F$23:$F$27,MATCH(D8,'Parâmetros'!$B$23:$B$27,0)),"")} -> 2950 | J8: =IF(H8="","",H8-I8) -> 4550 | K8: 46204 | L8: 7500 | Q8: =L8+N8+P8 -> 7500 | R8: =IF(H8="","",IF(ROUND(Q8-H8,2)=0,"OK","≠")) -> OK
B9: Produção Jr | C9: Elogroup | D9: Bronze | E9: {=IFERROR(INDEX('Parâmetros'!$C$23:$C$27,MATCH(D9,'Parâmetros'!$B$23:$B$27,0)),"")} -> 7500 | F9: Fechado | H9: 9500 | I9: {=IFERROR(INDEX('Parâmetros'!$F$23:$F$27,MATCH(D9,'Parâmetros'!$B$23:$B$27,0)),"")} -> 2950 | J9: =IF(H9="","",H9-I9) -> 6550 | K9: 46233 | L9: 9500 | Q9: =L9+N9+P9 -> 9500 | R9: =IF(H9="","",IF(ROUND(Q9-H9,2)=0,"OK","≠")) -> OK
B10: EESC Jr | C10: PECEGE | D10: Prata | E10: {=IFERROR(INDEX('Parâmetros'!$C$23:$C$27,MATCH(D10,'Parâmetros'!$B$23:$B$27,0)),"")} -> 11500 | F10: Fechado | H10: 11500 | I10: {=IFERROR(INDEX('Parâmetros'!$F$23:$F$27,MATCH(D10,'Parâmetros'!$B$23:$B$27,0)),"")} -> 3950 | J10: =IF(H10="","",H10-I10) -> 7550 | K10: 46254 | L10: 11500 | Q10: =L10+N10+P10 -> 11500 | R10: =IF(H10="","",IF(ROUND(Q10-H10,2)=0,"OK","≠")) -> OK
B11: EESC Jr | C11: MINERVA | D11: Bronze | E11: {=IFERROR(INDEX('Parâmetros'!$C$23:$C$27,MATCH(D11,'Parâmetros'!$B$23:$B$27,0)),"")} -> 7500 | F11: Fechado | H11: 7500 | I11: {=IFERROR(INDEX('Parâmetros'!$F$23:$F$27,MATCH(D11,'Parâmetros'!$B$23:$B$27,0)),"")} -> 2950 | J11: =IF(H11="","",H11-I11) -> 4550 | K11: 46279 | L11: 7500 | Q11: =L11+N11+P11 -> 7500 | R11: =IF(H11="","",IF(ROUND(Q11-H11,2)=0,"OK","≠")) -> OK
B12: Produção Jr | C12: Mastercard | D12: Bronze | E12: {=IFERROR(INDEX('Parâmetros'!$C$23:$C$27,MATCH(D12,'Parâmetros'!$B$23:$B$27,0)),"")} -> 7500 | F12: Fechado | H12: 5500 | I12: {=IFERROR(INDEX('Parâmetros'!$F$23:$F$27,MATCH(D12,'Parâmetros'!$B$23:$B$27,0)),"")} -> 2950 | J12: =IF(H12="","",H12-I12) -> 2550 | N12: 0 | P12: 0 | Q12: =L12+N12+P12 -> 0 | R12: =IF(H12="","",IF(ROUND(Q12-H12,2)=0,"OK","≠")) -> ≠
B13: Produção Jr | C13: Monks | D13: Bronze | E13: {=IFERROR(INDEX('Parâmetros'!$C$23:$C$27,MATCH(D13,'Parâmetros'!$B$23:$B$27,0)),"")} -> 7500 | F13: Fechado | H13: 7500 | I13: {=IFERROR(INDEX('Parâmetros'!$F$23:$F$27,MATCH(D13,'Parâmetros'!$B$23:$B$27,0)),"")} -> 2950 | J13: =IF(H13="","",H13-I13) -> 4550 | K13: 46265 | L13: 7500 | Q13: =L13+N13+P13 -> 7500 | R13: =IF(H13="","",IF(ROUND(Q13-H13,2)=0,"OK","≠")) -> OK
B14: Produção Jr | C14: Kis Solutions | D14: Bronze | E14: {=IFERROR(INDEX('Parâmetros'!$C$23:$C$27,MATCH(D14,'Parâmetros'!$B$23:$B$27,0)),"")} -> 7500 | F14: Fechado | H14: 7500 | I14: {=IFERROR(INDEX('Parâmetros'!$F$23:$F$27,MATCH(D14,'Parâmetros'!$B$23:$B$27,0)),"")} -> 2950 | J14: =IF(H14="","",H14-I14) -> 4550 | K14: 46275 | L14: 7500 | Q14: =L14+N14+P14 -> 7500 | R14: =IF(H14="","",IF(ROUND(Q14-H14,2)=0,"OK","≠")) -> OK
B15: Produção Jr | C15: WildLife | D15: Prata | E15: {=IFERROR(INDEX('Parâmetros'!$C$23:$C$27,MATCH(D15,'Parâmetros'!$B$23:$B$27,0)),"")} -> 11500 | F15: Fechado | H15: 11500 | I15: {=IFERROR(INDEX('Parâmetros'!$F$23:$F$27,MATCH(D15,'Parâmetros'!$B$23:$B$27,0)),"")} -> 3950 | J15: =IF(H15="","",H15-I15) -> 7550 | K15: 46255 | L15: 11500 | Q15: =L15+N15+P15 -> 11500 | R15: =IF(H15="","",IF(ROUND(Q15-H15,2)=0,"OK","≠")) -> OK
B16: Produção Jr | C16: Smart Dent | D16: Bronze | E16: {=IFERROR(INDEX('Parâmetros'!$C$23:$C$27,MATCH(D16,'Parâmetros'!$B$23:$B$27,0)),"")} -> 7500 | F16: Fechado | H16: 7500 | I16: {=IFERROR(INDEX('Parâmetros'!$F$23:$F$27,MATCH(D16,'Parâmetros'!$B$23:$B$27,0)),"")} -> 2950 | J16: =IF(H16="","",H16-I16) -> 4550 | K16: 46244 | L16: 3750 | M16: 46275 | N16: 3750 | Q16: =L16+N16+P16 -> 7500 | R16: =IF(H16="","",IF(ROUND(Q16-H16,2)=0,"OK","≠")) -> OK
B17: EESC Jr | C17: Unilever | D17: Bronze | E17: {=IFERROR(INDEX('Parâmetros'!$C$23:$C$27,MATCH(D17,'Parâmetros'!$B$23:$B$27,0)),"")} -> 7500 | F17: Fechado | H17: 7500 | I17: {=IFERROR(INDEX('Parâmetros'!$F$23:$F$27,MATCH(D17,'Parâmetros'!$B$23:$B$27,0)),"")} -> 2950 | J17: =IF(H17="","",H17-I17) -> 4550 | K17: 46305 | L17: 7500 | Q17: =L17+N17+P17 -> 7500 | R17: =IF(H17="","",IF(ROUND(Q17-H17,2)=0,"OK","≠")) -> OK
B18: EESC Jr | C18: Symrise | D18: Bronze | E18: {=IFERROR(INDEX('Parâmetros'!$C$23:$C$27,MATCH(D18,'Parâmetros'!$B$23:$B$27,0)),"")} -> 7500 | F18: Fechado | H18: 7500 | I18: {=IFERROR(INDEX('Parâmetros'!$F$23:$F$27,MATCH(D18,'Parâmetros'!$B$23:$B$27,0)),"")} -> 2950 | J18: =IF(H18="","",H18-I18) -> 4550 | K18: 46275 | L18: 7500 | Q18: =L18+N18+P18 -> 7500 | R18: =IF(H18="","",IF(ROUND(Q18-H18,2)=0,"OK","≠")) -> OK
B19: EESC Jr | C19: Bain | D19: Bronze | E19: {=IFERROR(INDEX('Parâmetros'!$C$23:$C$27,MATCH(D19,'Parâmetros'!$B$23:$B$27,0)),"")} -> 7500 | F19: Fechado | H19: 7500 | I19: {=IFERROR(INDEX('Parâmetros'!$F$23:$F$27,MATCH(D19,'Parâmetros'!$B$23:$B$27,0)),"")} -> 2950 | J19: =IF(H19="","",H19-I19) -> 4550 | K19: 46266 | L19: 7500 | Q19: =L19+N19+P19 -> 7500 | R19: =IF(H19="","",IF(ROUND(Q19-H19,2)=0,"OK","≠")) -> OK
B20: EESC Jr | C20: Alupar | D20: Bronze | E20: {=IFERROR(INDEX('Parâmetros'!$C$23:$C$27,MATCH(D20,'Parâmetros'!$B$23:$B$27,0)),"")} -> 7500 | F20: Fechado | H20: 7500 | I20: {=IFERROR(INDEX('Parâmetros'!$F$23:$F$27,MATCH(D20,'Parâmetros'!$B$23:$B$27,0)),"")} -> 2950 | J20: =IF(H20="","",H20-I20) -> 4550 | K20: 46290 | L20: 7500 | Q20: =L20+N20+P20 -> 7500 | R20: =IF(H20="","",IF(ROUND(Q20-H20,2)=0,"OK","≠")) -> OK
B21: Produção Jr | C21: Jacto | D21: Prata | E21: {=IFERROR(INDEX('Parâmetros'!$C$23:$C$27,MATCH(D21,'Parâmetros'!$B$23:$B$27,0)),"")} -> 11500 | F21: Fechado | H21: 11500 | I21: {=IFERROR(INDEX('Parâmetros'!$F$23:$F$27,MATCH(D21,'Parâmetros'!$B$23:$B$27,0)),"")} -> 3950 | J21: =IF(H21="","",H21-I21) -> 7550 | K21: 46280 | L21: 11500 | Q21: =L21+N21+P21 -> 11500 | R21: =IF(H21="","",IF(ROUND(Q21-H21,2)=0,"OK","≠")) -> OK
B22: Produção Jr | C22: Andritz | D22: Prata | E22: {=IFERROR(INDEX('Parâmetros'!$C$23:$C$27,MATCH(D22,'Parâmetros'!$B$23:$B$27,0)),"")} -> 11500 | F22: Fechado | H22: 11500 | I22: {=IFERROR(INDEX('Parâmetros'!$F$23:$F$27,MATCH(D22,'Parâmetros'!$B$23:$B$27,0)),"")} -> 3950 | J22: =IF(H22="","",H22-I22) -> 7550 | Q22: =L22+N22+P22 -> 0 | R22: =IF(H22="","",IF(ROUND(Q22-H22,2)=0,"OK","≠")) -> ≠
B23: Produção Jr | C23: Qi Tech | D23: Prata | E23: 11000 | F23: Fechado | H23: 11000 | I23: {=IFERROR(INDEX('Parâmetros'!$F$23:$F$27,MATCH(D23,'Parâmetros'!$B$23:$B$27,0)),"")} -> 3950 | J23: =IF(H23="","",H23-I23) -> 7050 | Q23: =L23+N23+P23 -> 0 | R23: =IF(H23="","",IF(ROUND(Q23-H23,2)=0,"OK","≠")) -> ≠
B24: Produção Jr | C24: Husqvarna | D24: Bronze | E24: {=IFERROR(INDEX('Parâmetros'!$C$23:$C$27,MATCH(D24,'Parâmetros'!$B$23:$B$27,0)),"")} -> 7500 | F24: Fechado | H24: 7500 | I24: {=IFERROR(INDEX('Parâmetros'!$F$23:$F$27,MATCH(D24,'Parâmetros'!$B$23:$B$27,0)),"")} -> 2950 | J24: =IF(H24="","",H24-I24) -> 4550 | K24: 46265 | L24: 7500 | Q24: =L24+N24+P24 -> 7500 | R24: =IF(H24="","",IF(ROUND(Q24-H24,2)=0,"OK","≠")) -> OK
B25: Produção Jr | C25: Astra | D25: Bronze | E25: {=IFERROR(INDEX('Parâmetros'!$C$23:$C$27,MATCH(D25,'Parâmetros'!$B$23:$B$27,0)),"")} -> 7500 | F25: Fechado | H25: 7500 | I25: {=IFERROR(INDEX('Parâmetros'!$F$23:$F$27,MATCH(D25,'Parâmetros'!$B$23:$B$27,0)),"")} -> 2950 | J25: =IF(H25="","",H25-I25) -> 4550 | Q25: =L25+N25+P25 -> 0 | R25: =IF(H25="","",IF(ROUND(Q25-H25,2)=0,"OK","≠")) -> ≠
B26: Produção Jr | C26: Control ID | D26: Executivo | E26: {=IFERROR(INDEX('Parâmetros'!$C$23:$C$27,MATCH(D26,'Parâmetros'!$B$23:$B$27,0)),"")} -> 4000 | F26: Fechado | H26: 4000 | I26: {=IFERROR(INDEX('Parâmetros'!$F$23:$F$27,MATCH(D26,'Parâmetros'!$B$23:$B$27,0)),"")} -> 1500 | J26: =IF(H26="","",H26-I26) -> 2500 | K26: 46265 | L26: 4000 | Q26: =L26+N26+P26 -> 4000 | R26: =IF(H26="","",IF(ROUND(Q26-H26,2)=0,"OK","≠")) -> OK
B27: Produção Jr | C27: Yara | D27: Executivo | E27: {=IFERROR(INDEX('Parâmetros'!$C$23:$C$27,MATCH(D27,'Parâmetros'!$B$23:$B$27,0)),"")} -> 4000 | F27: Fechado | H27: 4000 | I27: {=IFERROR(INDEX('Parâmetros'!$F$23:$F$27,MATCH(D27,'Parâmetros'!$B$23:$B$27,0)),"")} -> 1500 | J27: =IF(H27="","",H27-I27) -> 2500 | K27: 46265 | L27: 4000 | Q27: =L27+N27+P27 -> 4000 | R27: =IF(H27="","",IF(ROUND(Q27-H27,2)=0,"OK","≠")) -> OK
B28: Produção Jr | C28: Huawei | D28: Executivo | E28: {=IFERROR(INDEX('Parâmetros'!$C$23:$C$27,MATCH(D28,'Parâmetros'!$B$23:$B$27,0)),"")} -> 4000 | F28: Fechado | H28: 4000 | I28: {=IFERROR(INDEX('Parâmetros'!$F$23:$F$27,MATCH(D28,'Parâmetros'!$B$23:$B$27,0)),"")} -> 1500 | J28: =IF(H28="","",H28-I28) -> 2500 | Q28: =L28+N28+P28 -> 0 | R28: =IF(H28="","",IF(ROUND(Q28-H28,2)=0,"OK","≠")) -> ≠
B29: Produção Jr | C29: Alcans | D29: Executivo | E29: {=IFERROR(INDEX('Parâmetros'!$C$23:$C$27,MATCH(D29,'Parâmetros'!$B$23:$B$27,0)),"")} -> 4000 | F29: Fechado | H29: 4000 | I29: {=IFERROR(INDEX('Parâmetros'!$F$23:$F$27,MATCH(D29,'Parâmetros'!$B$23:$B$27,0)),"")} -> 1500 | J29: =IF(H29="","",H29-I29) -> 2500 | K29: 46285 | L29: 2000 | M29: 46315 | Q29: =L29+N29+P29 -> 2000 | R29: =IF(H29="","",IF(ROUND(Q29-H29,2)=0,"OK","≠")) -> ≠
E30: {=IFERROR(INDEX('Parâmetros'!$C$23:$C$27,MATCH(D30,'Parâmetros'!$B$23:$B$27,0)),"")} | I30: {=IFERROR(INDEX('Parâmetros'!$F$23:$F$27,MATCH(D30,'Parâmetros'!$B$23:$B$27,0)),"")} | J30: =IF(H30="","",H30-I30) | Q30: =L30+N30+P30 -> 0 | R30: =IF(H30="","",IF(ROUND(Q30-H30,2)=0,"OK","≠"))
E31: {=IFERROR(INDEX('Parâmetros'!$C$23:$C$27,MATCH(D31,'Parâmetros'!$B$23:$B$27,0)),"")} | I31: {=IFERROR(INDEX('Parâmetros'!$F$23:$F$27,MATCH(D31,'Parâmetros'!$B$23:$B$27,0)),"")} | J31: =IF(H31="","",H31-I31) | Q31: =L31+N31+P31 -> 0 | R31: =IF(H31="","",IF(ROUND(Q31-H31,2)=0,"OK","≠"))
E32: {=IFERROR(INDEX('Parâmetros'!$C$23:$C$27,MATCH(D32,'Parâmetros'!$B$23:$B$27,0)),"")} | I32: {=IFERROR(INDEX('Parâmetros'!$F$23:$F$27,MATCH(D32,'Parâmetros'!$B$23:$B$27,0)),"")} | J32: =IF(H32="","",H32-I32) | Q32: =L32+N32+P32 -> 0 | R32: =IF(H32="","",IF(ROUND(Q32-H32,2)=0,"OK","≠"))
E33: {=IFERROR(INDEX('Parâmetros'!$C$23:$C$27,MATCH(D33,'Parâmetros'!$B$23:$B$27,0)),"")}
E34: {=IFERROR(INDEX('Parâmetros'!$C$23:$C$27,MATCH(D34,'Parâmetros'!$B$23:$B$27,0)),"")}
E35: {=IFERROR(INDEX('Parâmetros'!$C$23:$C$27,MATCH(D35,'Parâmetros'!$B$23:$B$27,0)),"")} | I35: {=IFERROR(INDEX('Parâmetros'!$F$23:$F$27,MATCH(D35,'Parâmetros'!$B$23:$B$27,0)),"")} | J35: =IF(H35="","",H35-I35) | Q35: =L35+N35+P35 -> 0 | R35: =IF(H35="","",IF(ROUND(Q35-H35,2)=0,"OK","≠"))
E36: {=IFERROR(INDEX('Parâmetros'!$C$23:$C$27,MATCH(D36,'Parâmetros'!$B$23:$B$27,0)),"")} | I36: {=IFERROR(INDEX('Parâmetros'!$F$23:$F$27,MATCH(D36,'Parâmetros'!$B$23:$B$27,0)),"")} | J36: =IF(H36="","",H36-I36) | Q36: =L36+N36+P36 -> 0 | R36: =IF(H36="","",IF(ROUND(Q36-H36,2)=0,"OK","≠"))
C38: TOTAL FECHADO | H38: =SUMIFS(H5:H36,F5:F36,"Fechado") -> 212000 | I38: =SUMIFS(I5:I36,F5:F36,"Fechado") -> 79900 | J38: =SUMIFS(J5:J36,F5:F36,"Fechado") -> 132100

Sheet Gastos Realizados
B2: GASTOS REALIZADOS - CONTROLE DE PAGAMENTO
B4: Categoria | C4: Descrição | D4: Status | E4: Marg.Seg. | F4: Valor Previsto | G4: Nº Parc. | H4: Pago PJ (R$) | I4: % PJ | J4: Pago EESC (R$) | K4: % EESC | L4: Total Pago | M4: % Pago | N4: OK? | O4: Observação
B5: Fixo Dtrip | C5: Gestão da Feira (contrato LGDM) | D5: Contratado | E5: Não | F5: 25257 | G5: 3 | H5: 16838 | I5: =IF(F5=0,0,H5/F5) -> 0.66666667 | J5: 0 | K5: =IF(F5=0,0,J5/F5) -> 0 | L5: =H5+J5 -> 16838 | M5: =IF(F5=0,0,L5/F5) -> 0.66666667 | N5: =IF(L5=0,"—",IF(ROUND(L5-F5,2)=0,"OK","parcial")) -> parcial
B6: Fixo Dtrip | C6: Lounge Expo | D6: Estimado | E6: Não | F6: 1390 | G6: 1 | H6: 0 | I6: =IF(F6=0,0,H6/F6) -> 0 | J6: 0 | K6: =IF(F6=0,0,J6/F6) -> 0 | L6: =H6+J6 -> 0 | M6: =IF(F6=0,0,L6/F6) -> 0 | N6: =IF(L6=0,"—",IF(ROUND(L6-F6,2)=0,"OK","parcial")) -> —
B7: Fixo Dtrip | C7: Pórtico de entrada | D7: Estimado | E7: Não | F7: 3250 | G7: 1 | H7: 0 | I7: =IF(F7=0,0,H7/F7) -> 0 | J7: 0 | K7: =IF(F7=0,0,J7/F7) -> 0 | L7: =H7+J7 -> 0 | M7: =IF(F7=0,0,L7/F7) -> 0 | N7: =IF(L7=0,"—",IF(ROUND(L7-F7,2)=0,"OK","parcial")) -> —
B8: Fixo Dtrip | C8: Backdrop de fotos | D8: Estimado | E8: Não | F8: 2933.5 | G8: 1 | H8: 0 | I8: =IF(F8=0,0,H8/F8) -> 0 | J8: 0 | K8: =IF(F8=0,0,J8/F8) -> 0 | L8: =H8+J8 -> 0 | M8: =IF(F8=0,0,L8/F8) -> 0 | N8: =IF(L8=0,"—",IF(ROUND(L8-F8,2)=0,"OK","parcial")) -> —
B9: Fixo Dtrip | C9: Roda de conversa | D9: Estimado | E9: Não | F9: 4442.5 | G9: 1 | H9: 0 | I9: =IF(F9=0,0,H9/F9) -> 0 | J9: 0 | K9: =IF(F9=0,0,J9/F9) -> 0 | L9: =H9+J9 -> 0 | M9: =IF(F9=0,0,L9/F9) -> 0 | N9: =IF(L9=0,"—",IF(ROUND(L9-F9,2)=0,"OK","parcial")) -> —
B10: Fixo Dtrip | C10: Impostos | D10: Estimado | E10: Não | F10: 10453.5 | G10: 1 | H10: 0 | I10: =IF(F10=0,0,H10/F10) -> 0 | J10: 0 | K10: =IF(F10=0,0,J10/F10) -> 0 | L10: =H10+J10 -> 0 | M10: =IF(F10=0,0,L10/F10) -> 0 | N10: =IF(L10=0,"—",IF(ROUND(L10-F10,2)=0,"OK","parcial")) -> —
B11: Fixo Dtrip | C11: Credenciamento | D11: Estimado | E11: Não | F11: 8685.5 | G11: 1 | H11: 0 | I11: =IF(F11=0,0,H11/F11) -> 0 | J11: 0 | K11: =IF(F11=0,0,J11/F11) -> 0 | L11: =H11+J11 -> 0 | M11: =IF(F11=0,0,L11/F11) -> 0 | N11: =IF(L11=0,"—",IF(ROUND(L11-F11,2)=0,"OK","parcial")) -> —
B12: Outros | C12: Marketing | D12: Estimado | E12: Sim | F12: 400 | G12: 1 | H12: 0 | I12: =IF(F12=0,0,H12/F12) -> 0 | J12: 0 | K12: =IF(F12=0,0,J12/F12) -> 0 | L12: =H12+J12 -> 0 | M12: =IF(F12=0,0,L12/F12) -> 0 | N12: =IF(L12=0,"—",IF(ROUND(L12-F12,2)=0,"OK","parcial")) -> —
B13: Outros | C13: EJUDI | D13: Estimado | E13: Não | F13: 2880 | G13: 6 | H13: 0 | I13: =IF(F13=0,0,H13/F13) -> 0 | J13: 0 | K13: =IF(F13=0,0,J13/F13) -> 0 | L13: =H13+J13 -> 0 | M13: =IF(F13=0,0,L13/F13) -> 0 | N13: =IF(L13=0,"—",IF(ROUND(L13-F13,2)=0,"OK","parcial")) -> —
B14: Outros | C14: Camisetas | D14: Estimado | E14: Sim | F14: 2280 | G14: 2 | H14: 2280 | I14: =IF(F14=0,0,H14/F14) -> 1 | J14: 0 | K14: =IF(F14=0,0,J14/F14) -> 0 | L14: =H14+J14 -> 2280 | M14: =IF(F14=0,0,L14/F14) -> 1 | N14: =IF(L14=0,"—",IF(ROUND(L14-F14,2)=0,"OK","parcial")) -> OK
B15: Outros | C15: Ambulância | D15: Estimado | E15: Sim | F15: 1500 | G15: 1 | H15: 0 | I15: =IF(F15=0,0,H15/F15) -> 0 | J15: 0 | K15: =IF(F15=0,0,J15/F15) -> 0 | L15: =H15+J15 -> 0 | M15: =IF(F15=0,0,L15/F15) -> 0 | N15: =IF(L15=0,"—",IF(ROUND(L15-F15,2)=0,"OK","parcial")) -> —
B16: Outros | C16: Transporte USP <> UFSCar | D16: Estimado | E16: Sim | F16: 300 | G16: 1 | H16: 0 | I16: =IF(F16=0,0,H16/F16) -> 0 | J16: 0 | K16: =IF(F16=0,0,J16/F16) -> 0 | L16: =H16+J16 -> 0 | M16: =IF(F16=0,0,L16/F16) -> 0 | N16: =IF(L16=0,"—",IF(ROUND(L16-F16,2)=0,"OK","parcial")) -> —
... B18: Outros | C18: Crachás | D18: Estimado | E18: Sim | F18: 1779.23 | G18: 1 | H18: 1779.23 | I18: =IF(F18=0,0,H18/F18) -> 1 | J18: 0 | K18: =IF(F18=0,0,J18/F18) -> 0 | L18: =H18+J18 -> 1779.23 | M18: =IF(F18=0,0,L18/F18) -> 1 | N18: =IF(L18=0,"—",IF(ROUND(L18-F18,2)=0,"OK","parcial")) -> OK
B19: Outros | C19: Bolsas - Brindes | D19: Contratado | E19: Sim | F19: 4375.41 | G19: 2 | H19: 4375.41 | L19: 4375.41 | N19: OK
B20: Outros | C20: Fotográfos | D20: Estimado | E20: Sim | F20: 1800 | G20: 2 | H20: 900 | L20: 900 | M20: =IF(F20=0,0,L20/F20) -> 0.5
B21: Outros | C21: Cartazes | D21: Estimado | E21: Sim | F21: 5 | G21: 1 | H21: 0 | I21: =IF(F21=0,0,H21/F21) -> 0 | J21: 0 | K21: =IF(F21=0,0,J21/F21) -> 0 | L21: =H21+J21 -> 0 | M21: =IF(F21=0,0,L21/F21) -> 0 | N21: =IF(L21=0,"—",IF(ROUND(L21-F21,2)=0,"OK","parcial")) -> —
B22: Outros | C22: Banners | D22: Estimado | E22: Sim | F22: 40 | G22: 1 | H22: 0 | I22: =IF(F22=0,0,H22/F22) -> 0 | J22: 0 | K22: =IF(F22=0,0,J22/F22) -> 0 | L22: =H22+J22 -> 0 | M22: =IF(F22=0,0,L22/F22) -> 0 | N22: =IF(L22=0,"—",IF(ROUND(L22-F22,2)=0,"OK","parcial")) -> —
B23: Outros | C23: Segurança | D23: Estimado | E23: Sim | F23: 480 | G23: 1 | H23: 0 | I23: =IF(F23=0,0,H23/F23) -> 0 | J23: 0 | K23: =IF(F23=0,0,J23/F23) -> 0 | L23: =H23+J23 -> 0 | M23: =IF(F23=0,0,L23/F23) -> 0 | N23: =IF(L23=0,"—",IF(ROUND(L23-F23,2)=0,"OK","parcial")) -> —
B24: Outros | C24: Coffee | D24: Estimado | E24: Sim | F24: 2400 | G24: 1 | H24: 0 | I24: =IF(F24=0,0,H24/F24) -> 0 | J24: 0 | K24: =IF(F24=0,0,J24/F24) -> 0 | L24: =H24+J24 -> 0 | M24: =IF(F24=0,0,L24/F24) -> 0 | N24: =IF(L24=0,"—",IF(ROUND(L24-F24,2)=0,"OK","parcial")) -> —
B25: Outros | C25: Gasto Geral (buffer) | D25: Estimado | E25: Sim | F25: 1000 | G25: 1 | H25: 0 | I25: =IF(F25=0,0,H25/F25) -> 0 | J25: 0 | K25: =IF(F25=0,0,J25/F25) -> 0 | L25: =H25+J25 -> 0 | M25: =IF(F25=0,0,L25/F25) -> 0 | N25: =IF(L25=0,"—",IF(ROUND(L25-F25,2)=0,"OK","parcial")) -> —
B26: Outros | C26: Sorteios | D26: Contratado | E26: Sim | F26: 921.01 | G26: 1 | H26: 921.01 | I26: =IF(F26=0,0,H26/F26) -> 1 | K26: =IF(F26=0,0,J26/F26) -> 0 | L26: =H26+J26 -> 921.01 | M26: =IF(F26=0,0,L26/F26) -> 1 | N26: =IF(L26=0,"—",IF(ROUND(L26-F26,2)=0,"OK","parcial")) -> OK
B27: Outros | C27: Credenciais | D27: Contratado | E27: Sim | F27: 213.21 | G27: 1 | I27: =IF(F27=0,0,H27/F27) -> 0 | J27: 213.21 | K27: =IF(F27=0,0,J27/F27) -> 1 | L27: =H27+J27 -> 213.21 | M27: =IF(F27=0,0,L27/F27) -> 1 | N27: =IF(L27=0,"—",IF(ROUND(L27-F27,2)=0,"OK","parcial")) -> OK
I28: =IF(F28=0,0,H28/F28) -> 0 | K28: =IF(F28=0,0,J28/F28) -> 0 | L28: =H28+J28 -> 0 | M28: =IF(F28=0,0,L28/F28) -> 0 | N28: =IF(L28=0,"—",IF(ROUND(L28-F28,2)=0,"OK","parcial")) -> —
I29: =IF(F29=0,0,H29/F29) -> 0 | K29: =IF(F29=0,0,J29/F29) -> 0 | L29: =H29+J29 -> 0 | M29: =IF(F29=0,0,L29/F29) -> 0 | N29: =IF(L29=0,"—",IF(ROUND(L29-F29,2)=0,"OK","parcial")) -> —
I30: =IF(F30=0,0,H30/F30) -> 0 | K30: =IF(F30=0,0,J30/F30) -> 0 | L30: =H30+J30 -> 0 | M30: =IF(F30=0,0,L30/F30) -> 0 | N30: =IF(L30=0,"—",IF(ROUND(L30-F30,2)=0,"OK","parcial")) -> —
I31: =IF(F31=0,0,H31/F31) -> 0 | K31: =IF(F31=0,0,J31/F31) -> 0 | L31: =H31+J31 -> 0 | M31: =IF(F31=0,0,L31/F31) -> 0 | N31: =IF(L31=0,"—",IF(ROUND(L31-F31,2)=0,"OK","parcial")) -> —
C33: TOTAL PAGO | F33: =SUM(F5:F31) -> 76915.86 | H33: =SUM(H5:H31) -> 27093.65 | J33: =SUM(J5:J31) -> 213.21 | L33: =SUM(L5:L31) -> 27306.86

Sheet Fluxo de Caixa
B2: FLUXO DE CAIXA MENSAL DO EVENTO
B4: Período | C4: Jul | D4: Ago | E4: Set | F4: Out | G4: Nov | H4: Dez | I4: Total
B5: ENTRADAS (recebimentos)
B6: Produção Jr | C6: =SUMPRODUCT((Vendas!$B$5:$B$36="Produção Jr")*(Vendas!$F$5:$F$36<>"Cancelado")*(Vendas!$K$5:$K$36>=DATE(2026,7,1))*(Vendas!$K$5:$K$36<DATE(2026,8,1))*Vendas!$L$5:$L$36)+SUMPRODUCT((Vendas!$B$5:$B$36="Produção Jr")*(Vendas!$F$5:$F$36<>"Cancelado")*(Vendas!$M$5:$M$36>=DATE(2026,7,1))*(Vendas!$M$5:$M$36<DATE(2026,8,1))*Vendas!$N$5:$N$36)+SUMPRODUCT((Vendas!$B$5:$B$36="Produção Jr")*(Vendas!$F$5:$F$36<>"Cancelado")*(Vendas!$O$5:$O$36>=DATE(2026,7,1))*(Vendas!$O$5:$O$36<DATE(2026,8,1))*Vendas!$P$5:$P$36) -> 47000 | D6: =SUMPRODUCT((Vendas!$B$5:$B$36="Produção Jr")*(Vendas!$F$5:$F$36<>"Cancelado")*(Vendas!$K$5:$K$36>=DATE(2026,8,1))*(Vendas!$K$5:$K$36<DATE(2026,9,1))*Vendas!$L$5:$L$36)+SUMPRODUCT((Vendas!$B$5:$B$36="Produção Jr")*(Vendas!$F$5:$F$36<>"Cancelado")*(Vendas!$M$5:$M$36>=DATE(2026,8,1))*(Vendas!$M$5:$M$36<DATE(2026,9,1))*Vendas!$N$5:$N$36)+SUMPRODUCT((Vendas!$B$5:$B$36="Produção Jr")*(Vendas!$F$5:$F$36<>"Cancelado")*(Vendas!$O$5:$O$36>=DATE(2026,8,1))*(Vendas!$O$5:$O$36<DATE(2026,9,1))*Vendas!$P$5:$P$36) -> 49750 | E6: =SUMPRODUCT((Vendas!$B$5:$B$36="Produção Jr")*(Vendas!$F$5:$F$36<>"Cancelado")*(Vendas!$K$5:$K$36>=DATE(2026,9,1))*(Vendas!$K$5:$K$36<DATE(2026,10,1))*Vendas!$L$5:$L$36)+SUMPRODUCT((Vendas!$B$5:$B$36="Produção Jr")*(Vendas!$F$5:$F$36<>"Cancelado")*(Vendas!$M$5:$M$36>=DATE(2026,9,1))*(Vendas!$M$5:$M$36<DATE(2026,10,1))*Vendas!$N$5:$N$36)+SUMPRODUCT((Vendas!$B$5:$B$36="Produção Jr")*(Vendas!$F$5:$F$36<>"Cancelado")*(Vendas!$O$5:$O$36>=DATE(2026,9,1))*(Vendas!$O$5:$O$36<DATE(2026,10,1))*Vendas!$P$5:$P$36) -> 24750 | F6: =SUMPRODUCT((Vendas!$B$5:$B$36="Produção Jr")*(Vendas!$F$5:$F$36<>"Cancelado")*(Vendas!$K$5:$K$36>=DATE(2026,10,1))*(Vendas!$K$5:$K$36<DATE(2026,11,1))*Vendas!$L$5:$L$36)+SUMPRODUCT((Vendas!$B$5:$B$36="Produção Jr")*(Vendas!$F$5:$F$36<>"Cancelado")*(Vendas!$M$5:$M$36>=DATE(2026,10,1))*(Vendas!$M$5:$M$36<DATE(2026,11,1))*Vendas!$N$5:$N$36)+SUMPRODUCT((Vendas!$B$5:$B$36="Produção Jr")*(Vendas!$F$5:$F$36<>"Cancelado")*(Vendas!$O$5:$O$36>=DATE(2026,10,1))*(Vendas!$O$5:$O$36<DATE(2026,11,1))*Vendas!$P$5:$P$36) -> 0 | G6: =SUMPRODUCT((Vendas!$B$5:$B$36="Produção Jr")*(Vendas!$F$5:$F$36<>"Cancelado")*(Vendas!$K$5:$K$36>=DATE(2026,11,1))*(Vendas!$K$5:$K$36<DATE(2026,12,1))*Vendas!$L$5:$L$36)+SUMPRODUCT((Vendas!$B$5:$B$36="Produção Jr")*(Vendas!$F$5:$F$36<>"Cancelado")*(Vendas!$M$5:$M$36>=DATE(2026,11,1))*(Vendas!$M$5:$M$36<DATE(2026,12,1))*Vendas!$N$5:$N$36)+SUMPRODUCT((Vendas!$B$5:$B$36="Produção Jr")*(Vendas!$F$5:$F$36<>"Cancelado")*(Vendas!$O$5:$O$36>=DATE(2026,11,1))*(Vendas!$O$5:$O$36<DATE(2026,12,1))*Vendas!$P$5:$P$36) -> 0 | H6: =SUMPRODUCT((Vendas!$B$5:$B$36="Produção Jr")*(Vendas!$F$5:$F$36<>"Cancelado")*(Vendas!$K$5:$K$36>=DATE(2026,12,1))*(Vendas!$K$5:$K$36<DATE(2027,1,1))*Vendas!$L$5:$L$36)+SUMPRODUCT((Vendas!$B$5:$B$36="Produção Jr")*(Vendas!$F$5:$F$36<>"Cancelado")*(Vendas!$M$5:$M$36>=DATE(2026,12,1))*(Vendas!$M$5:$M$36<DATE(2027,1,1))*Vendas!$N$5:$N$36)+SUMPRODUCT((Vendas!$B$5:$B$36="Produção Jr")*(Vendas!$F$5:$F$36<>"Cancelado")*(Vendas!$O$5:$O$36>=DATE(2026,12,1))*(Vendas!$O$5:$O$36<DATE(2027,1,1))*Vendas!$P$5:$P$36) -> 0 | I6: =SUM(C6:H6) -> 121500
B7: EESC Jr | C7: =SUMPRODUCT((Vendas!$B$5:$B$36="EESC Jr")*(Vendas!$F$5:$F$36<>"Cancelado")*(Vendas!$K$5:$K$36>=DATE(2026,7,1))*(Vendas!$K$5:$K$36<DATE(2026,8,1))*Vendas!$L$5:$L$36)+SUMPRODUCT((Vendas!$B$5:$B$36="EESC Jr")*(Vendas!$F$5:$F$36<>"Cancelado")*(Vendas!$M$5:$M$36>=DATE(2026,7,1))*(Vendas!$M$5:$M$36<DATE(2026,8,1))*Vendas!$N$5:$N$36)+SUMPRODUCT((Vendas!$B$5:$B$36="EESC Jr")*(Vendas!$F$5:$F$36<>"Cancelado")*(Vendas!$O$5:$O$36>=DATE(2026,7,1))*(Vendas!$O$5:$O$36<DATE(2026,8,1))*Vendas!$P$5:$P$36) -> 0 | D7: =SUMPRODUCT((Vendas!$B$5:$B$36="EESC Jr")*(Vendas!$F$5:$F$36<>"Cancelado")*(Vendas!$K$5:$K$36>=DATE(2026,8,1))*(Vendas!$K$5:$K$36<DATE(2026,9,1))*Vendas!$L$5:$L$36)+SUMPRODUCT((Vendas!$B$5:$B$36="EESC Jr")*(Vendas!$F$5:$F$36<>"Cancelado")*(Vendas!$M$5:$M$36>=DATE(2026,8,1))*(Vendas!$M$5:$M$36<DATE(2026,9,1))*Vendas!$N$5:$N$36)+SUMPRODUCT((Vendas!$B$5:$B$36="EESC Jr")*(Vendas!$F$5:$F$36<>"Cancelado")*(Vendas!$O$5:$O$36>=DATE(2026,8,1))*(Vendas!$O$5:$O$36<DATE(2026,9,1))*Vendas!$P$5:$P$36) -> 11500 | E7: =SUMPRODUCT((Vendas!$B$5:$B$36="EESC Jr")*(Vendas!$F$5:$F$36<>"Cancelado")*(Vendas!$K$5:$K$36>=DATE(2026,9,1))*(Vendas!$K$5:$K$36<DATE(2026,10,1))*Vendas!$L$5:$L$36)+SUMPRODUCT((Vendas!$B$5:$B$36="EESC Jr")*(Vendas!$F$5:$F$36<>"Cancelado")*(Vendas!$M$5:$M$36>=DATE(2026,9,1))*(Vendas!$M$5:$M$36<DATE(2026,10,1))*Vendas!$N$5:$N$36)+SUMPRODUCT((Vendas!$B$5:$B$36="EESC Jr")*(Vendas!$F$5:$F$36<>"Cancelado")*(Vendas!$O$5:$O$36>=DATE(2026,9,1))*(Vendas!$O$5:$O$36<DATE(2026,10,1))*Vendas!$P$5:$P$36) -> 30000 | F7: =SUMPRODUCT((Vendas!$B$5:$B$36="EESC Jr")*(Vendas!$F$5:$F$36<>"Cancelado")*(Vendas!$K$5:$K$36>=DATE(2026,10,1))*(Vendas!$K$5:$K$36<DATE(2026,11,1))*Vendas!$L$5:$L$36)+SUMPRODUCT((Vendas!$B$5:$B$36="EESC Jr")*(Vendas!$F$5:$F$36<>"Cancelado")*(Vendas!$M$5:$M$36>=DATE(2026,10,1))*(Vendas!$M$5:$M$36<DATE(2026,11,1))*Vendas!$N$5:$N$36)+SUMPRODUCT((Vendas!$B$5:$B$36="EESC Jr")*(Vendas!$F$5:$F$36<>"Cancelado")*(Vendas!$O$5:$O$36>=DATE(2026,10,1))*(Vendas!$O$5:$O$36<DATE(2026,11,1))*Vendas!$P$5:$P$36) -> 7500 | G7: =SUMPRODUCT((Vendas!$B$5:$B$36="EESC Jr")*(Vendas!$F$5:$F$36<>"Cancelado")*(Vendas!$K$5:$K$36>=DATE(2026,11,1))*(Vendas!$K$5:$K$36<DATE(2026,12,1))*Vendas!$L$5:$L$36)+SUMPRODUCT((Vendas!$B$5:$B$36="EESC Jr")*(Vendas!$F$5:$F$36<>"Cancelado")*(Vendas!$M$5:$M$36>=DATE(2026,11,1))*(Vendas!$M$5:$M$36<DATE(2026,12,1))*Vendas!$N$5:$N$36)+SUMPRODUCT((Vendas!$B$5:$B$36="EESC Jr")*(Vendas!$F$5:$F$36<>"Cancelado")*(Vendas!$O$5:$O$36>=DATE(2026,11,1))*(Vendas!$O$5:$O$36<DATE(2026,12,1))*Vendas!$P$5:$P$36) -> 0 | H7: =SUMPRODUCT((Vendas!$B$5:$B$36="EESC Jr")*(Vendas!$F$5:$F$36<>"Cancelado")*(Vendas!$K$5:$K$36>=DATE(2026,12,1))*(Vendas!$K$5:$K$36<DATE(2027,1,1))*Vendas!$L$5:$L$36)+SUMPRODUCT((Vendas!$B$5:$B$36="EESC Jr")*(Vendas!$F$5:$F$36<>"Cancelado")*(Vendas!$M$5:$M$36>=DATE(2026,12,1))*(Vendas!$M$5:$M$36<DATE(2027,1,1))*Vendas!$N$5:$N$36)+SUMPRODUCT((Vendas!$B$5:$B$36="EESC Jr")*(Vendas!$F$5:$F$36<>"Cancelado")*(Vendas!$O$5:$O$36>=DATE(2026,12,1))*(Vendas!$O$5:$O$36<DATE(2027,1,1))*Vendas!$P$5:$P$36) -> 0 | I7: =SUM(C7:H7) -> 49000
B8: Total de Entradas | C8: =SUM(C6:C7) -> 47000 | D8: =SUM(D6:D7) -> 61250 | E8: =SUM(E6:E7) -> 54750 | F8: =SUM(F6:F7) -> 7500 | G8: =SUM(G6:G7) -> 0 | H8: =SUM(H6:H7) -> 0 | I8: =SUM(I6:I7) -> 170500
B10: SAÍDAS (pagamentos previstos)
B11: Fixos Dtrip | C11: ='Gastos Previstos'!D22 -> 8419 | D11: ='Gastos Previstos'!E22 -> 8419 | E11: ='Gastos Previstos'!F22 -> 52382.24 | F11: ='Gastos Previstos'!G22 -> 0 | G11: ='Gastos Previstos'!H22 -> 0 | H11: ='Gastos Previstos'!I22 -> 0 | I11: =SUM(C11:H11) -> 69220.24
B12: Estandes (variável) | C12: ='Gastos Previstos'!D29 -> 0 | D12: ='Gastos Previstos'!E29 -> 0 | E12: ='Gastos Previstos'!F29 -> 79900 | F12: ='Gastos Previstos'!G29 -> 0 | G12: ='Gastos Previstos'!H29 -> 0 | H12: ='Gastos Previstos'!I29 -> 0 | I12: =SUM(C12:H12) -> 79900
B13: Outros gastos | C13: ='Gastos Previstos'!D48 -> 2520 | D13: ='Gastos Previstos'!E48 -> 6985.23 | E13: ='Gastos Previstos'!F48 -> 24531.42 | F13: ='Gastos Previstos'!G48 -> 480 | G13: ='Gastos Previstos'!H48 -> 0 | H13: ='Gastos Previstos'!I48 -> 0 | I13: =SUM(C13:H13) -> 34516.65
B14: Total de Saídas | C14: =SUM(C11:C13) -> 10939 | D14: =SUM(D11:D13) -> 15404.23 | E14: =SUM(E11:E13) -> 156813.66 | F14: =SUM(F11:F13) -> 480 | G14: =SUM(G11:G13) -> 0 | H14: =SUM(H11:H13) -> 0 | I14: =SUM(I11:I13) -> 183636.89
B16: RESULTADO DO MÊS | C16: =C8-C14 -> 36061 | D16: =D8-D14 -> 45845.77 | E16: =E8-E14 -> -102063.66 | F16: =F8-F14 -> 7020 | G16: =G8-G14 -> 0 | H16: =H8-H14 -> 0 | I16: =I8-I14 -> -13136.89
B17: SALDO ACUMULADO | C17: ='Parâmetros'!$C$12+C16 -> 36061 | D17: =C17+D16 -> 81906.77 | E17: =D17+E16 -> -20156.89 | F17: =E17+F16 -> -13136.89 | G17: =F17+G16 -> -13136.89 | H17: =G17+H16 -> -13136.89
B19: Caixa que as EJs precisam ter no pior mês | C19: =MAX(0,-MIN(C17:H17)) -> 20156.89
B20: Fica negativo em algum mês? | C20: =IF(MIN(C17:H17)<0,"SIM","Não") -> SIM

Sheet Previsão de Receita
B2: PREVISÃO DE RECEITA - SIMULAÇÃO DE CENÁRIOS
B5: STATUS HOJE (só com o que já está fechado)
B6: Faturamento fechado (tabela) | C6: =SUMIFS(Vendas!$E$5:$E$36,Vendas!$F$5:$F$36,"Fechado") -> 212000
B7: Gastos fixos (independem da venda) | C7: ='Gastos Previstos'!$C$22+'Gastos Previstos'!$C$48 -> 104696.89
B8: Margem já gerada pelos estandes fechados | C8: =SUMIFS(Vendas!$J$5:$J$36,Vendas!$F$5:$F$36,"Fechado") -> 132100
B9: Resultado hoje (margem fechada − fixos) | C9: =C8-C7 -> 27403.11
B10: Status | C10: =IF(C9>=0,"NO AZUL — já cobre os gastos fixos","NO VERMELHO — falta gerar margem") -> NO AZUL — já cobre os gastos fixos
B12: SIMULAÇÃO — ESTANDES A FECHAR POR CENÁRIO
B13: Pacote | C13: Preço Tabela | D13: Cotas Totais | E13: Já Fechados | F13: Disponíveis | G13: Pessimista | H13: Realista | I13: Otimista
B14: Executivo | C14: ='Parâmetros'!C23 -> 4000 | D14: ='Parâmetros'!E23 -> 27 | E14: =SUMPRODUCT((Vendas!$D$5:$D$36="Executivo")*(Vendas!$F$5:$F$36="Fechado")) -> 4 | F14: =D14-E14 -> 23
B15: Bronze | C15: ='Parâmetros'!C24 -> 7500 | D15: ='Parâmetros'!E24 -> 10 | E15: =SUMPRODUCT((Vendas!$D$5:$D$36="Bronze")*(Vendas!$F$5:$F$36="Fechado")) -> 13 | F15: =D15-E15 -> -3
B16: Prata | C16: ='Parâmetros'!C25 -> 11500 | D16: ='Parâmetros'!E25 -> 4 | E16: =SUMPRODUCT((Vendas!$D$5:$D$36="Prata")*(Vendas!$F$5:$F$36="Fechado")) -> 6 | F16: =D16-E16 -> -2
B17: Ouro | C17: ='Parâmetros'!C26 -> 15000 | D17: ='Parâmetros'!E26 -> 2 | E17: =SUMPRODUCT((Vendas!$D$5:$D$36="Ouro")*(Vendas!$F$5:$F$36="Fechado")) -> 2 | F17: =D17-E17 -> 0
B18: Patrocínio | C18: ='Parâmetros'!C27 -> 3000 | D18: ='Parâmetros'!E27 -> 30 | E18: =SUMPRODUCT((Vendas!$D$5:$D$36="Patrocínio")*(Vendas!$F$5:$F$36="Fechado")) -> 0 | F18: =D18-E18 -> 30
B20: RESULTADO POR CENÁRIO
B21: Indicador | C21: Já Fechado | D21: Pessimista | E21: Realista | F21: Otimista
B22: Faturamento a fechar (adicional) | C22: 0 | D22: =SUMPRODUCT(G14:G18,C14:C18) -> 0 | E22: =SUMPRODUCT(H14:H18,C14:C18) -> 0 | F22: =SUMPRODUCT(I14:I18,C14:C18) -> 0
B23: Faturamento TOTAL previsto | C23: =$C$6 -> 212000 | D23: =$C$6+D22 -> 212000 | E23: =$C$6+E22 -> 212000 | F23: =$C$6+F22 -> 212000
B24: Gastos fixos (não dependem de venda) | C24: =$C$7 -> 104696.89 | D24: =$C$7 -> 104696.89 | E24: =$C$7 -> 104696.89 | F24: =$C$7 -> 104696.89
B25: Custo dos estandes (do cenário) | C25: =SUMPRODUCT(E14:E18,'Parâmetros'!$F$23:$F$27) -> 79900 | D25: =SUMPRODUCT(E14:E18,'Parâmetros'!$F$23:$F$27)+SUMPRODUCT(G14:G18,'Parâmetros'!$F$23:$F$27) -> 79900 | E25: =SUMPRODUCT(E14:E18,'Parâmetros'!$F$23:$F$27)+SUMPRODUCT(H14:H18,'Parâmetros'!$F$23:$F$27) -> 79900 | F25: =SUMPRODUCT(E14:E18,'Parâmetros'!$F$23:$F$27)+SUMPRODUCT(I14:I18,'Parâmetros'!$F$23:$F$27) -> 79900
B26: Gasto total do evento | C26: =C24+C25 -> 184596.89 | D26: =D24+D25 -> 184596.89 | E26: =E24+E25 -> 184596.89 | F26: =F24+F25 -> 184596.89
B27: RESULTADO (fat − gasto) | C27: =C23-C26 -> 27403.11 | D27: =D23-D26 -> 27403.11 | E27: =E23-E26 -> 27403.11 | F27: =F23-F26 -> 27403.11
B28: Dá lucro? | C28: =IF(C27>=0,"SIM","NÃO") -> SIM | D28: =IF(D27>=0,"SIM","NÃO") -> SIM | E28: =IF(E27>=0,"SIM","NÃO") -> SIM | F28: =IF(F27>=0,"SIM","NÃO") -> SIM
B30: QUANTOS ESTANDES AINDA FALTAM PARA NÃO TER PREJUÍZO
B31: Margem que ainda falta cobrir | C31: =MAX(0,C7-C8) -> 0
B32: Traduzido em estandes de um único pacote:
B33: Pacote | C33: Preço Tabela | D33: Margem Unitária | E33: Estandes necessários (se só esse)
B34: Executivo | C34: =C14 -> 4000 | D34: =VLOOKUP(B34,'Parâmetros'!$B$23:$G$27,6,0) -> 2500 | E34: =IF($C$31<=0,"— já cobre",ROUNDUP($C$31/D34,0)) -> — já cobre
B35: Bronze | C35: =C15 -> 7500 | D35: =VLOOKUP(B35,'Parâmetros'!$B$23:$G$27,6,0) -> 4550 | E35: =IF($C$31<=0,"— já cobre",ROUNDUP($C$31/D35,0)) -> — já cobre
B36: Prata | C36: =C16 -> 11500 | D36: =VLOOKUP(B36,'Parâmetros'!$B$23:$G$27,6,0) -> 7550 | E36: =IF($C$31<=0,"— já cobre",ROUNDUP($C$31/D36,0)) -> — já cobre
B37: Ouro | C37: =C17 -> 15000 | D37: =VLOOKUP(B37,'Parâmetros'!$B$23:$G$27,6,0) -> 9075 | E37: =IF($C$31<=0,"— já cobre",ROUNDUP($C$31/D37,0)) -> — já cobre
B38: Patrocínio | C38: =C18 -> 3000 | D38: =VLOOKUP(B38,'Parâmetros'!$B$23:$G$27,6,0) -> 3000 | E38: =IF($C$31<=0,"— já cobre",ROUNDUP($C$31/D38,0)) -> — já cobre

Sheet Parâmetros
B2: FEIRA DE MERCADO 2026 - PARÂMETROS
B5: DATAS
B6: Data-base (hoje) | C6: 46223
B7: Evento — 1º dia | C7: 46266
B8: Evento — 2º dia | C8: 46267
B10: PREMISSAS
B11: Margem de segurança sobre estimativas | C11: 0.2
B12: Saldo inicial do caixa do evento | C12: 0
B13: % estandes pago na contratação | C13: 0.5
B14: Estandes — mês 1ª parcela | C14: ago/26
B15: Estandes — mês 2ª parcela | C15: set/26
B17: EMPRESAS JUNIORES
B18: EJ 1 | C18: Produção Jr
B19: EJ 2 | C19: EESC Jr
B21: TABELA DE PACOTES
B22: Pacote | C22: Preço Tabela | D22: Preço Mínimo | E22: Cotas | F22: Custo Estande | G22: Margem Unit. | H22: Fat. Máx (tabela)
B23: Executivo | C23: 4000 | D23: 3500 | E23: 27 | F23: 1500 | G23: =C23-F23 -> 2500 | H23: =C23*E23 -> 108000
B24: Bronze | C24: 7500 | D24: 6500 | E24: 10 | F24: 2950 | G24: =C24-F24 -> 4550 | H24: =C24*E24 -> 75000
B25: Prata | C25: 11500 | D25: 10000 | E25: 4 | F25: 3950 | G25: =C25-F25 -> 7550 | H25: =C25*E25 -> 46000
B26: Ouro | C26: 15000 | D26: 15000 | E26: 2 | F26: 5925 | G26: =C26-F26 -> 9075 | H26: =C26*E26 -> 30000
B27: Patrocínio | C27: 3000 | D27: 3000 | E27: 30 | F27: 0 | G27: =C27-F27 -> 3000 | H27: =C27*E27 -> 90000
B28: TOTAL | E28: =SUM(E23:E27) -> 73 | H28: =SUM(H23:H27) -> 349000
